<?xmal version="1.0"?>
<robot xmlns:xacro='https://ros.org/wiki/xacro' name='urdf_test'>
    <xacro:include filename="macros.xacro"/>
    <xacro:property name="wheel_diameter" value="0.068"/>
    <xacro:property name="wheel_speration" value="0.180"/>
    <material name="white">
        <color rgba="1 1 1 1" />
    </material>

    <link name = 'base_link'/>

    <joint name = 'body_joint' type='fixed'>
        <parent link='base_link'/>
        <child link = 'robot_body'/>
        <origin xyz="0.0 0.0 0.0" rpy="0.0 0.0 0.0"/>
    </joint>

    <link name="robot_body">
        <visual>
            <origin xyz="0 0 0" rpy="0 0 0"/>
            <geometry>
                <mesh filename="package://description/meshes/robot_b/robot_b_body.stl" scale="0.001 0.001 0.001"/>
            </geometry>
            <material name="white"/>
        </visual>
        <collision>
            <origin xyz="0.0 0.0 0.0" rpy="0.0 0.0 0.0"/>
            <geometry>
                <mesh filename="package://description/meshes/robot_b/robot_b_body.stl" scale="0.001 0.001 0.001"/>
            </geometry>
        </collision>
    </link>
    <!-- <gazebo reference='robot_body'>
        <material>Gazebo/White</material>
    </gazebo> -->

    <joint name="r_wheel_joint" type="continuous">
        <parent link='robot_body'/>
        <child link='r_wheel'/>0
        <origin xyz="0.05 0.168 0.168" rpy="0 -1.57 0"/>
        <axis xyz='0 0 1'/>
    </joint>

    <link name="r_wheel">
        <visual>
            <origin xyz="-0.168 -0.168 0.05" rpy="0 1.57 0"/>
            <geometry>
                <mesh filename="package://description/meshes/robot_b/robot_b_r_wheel.stl" scale="0.001 0.001 0.001"/>
            </geometry>
        </visual>
        <collision>
            <origin xyz="-0.168 -0.168 0.05" rpy="0 1.57 0"/>
            <geometry>
                <mesh filename="package://description/meshes/robot_b/robot_b_r_wheel.stl" scale="0.001 0.001 0.001"/>
            </geometry>
        </collision>
    </link>
    <!-- <gazebo reference='r_wheel'>
        <material>Gazebo/Black</material>
    </gazebo> -->

    <joint name="l_wheel_joint" type="continuous">
        <origin xyz="0.50 0.168 0.168" rpy="0 1.57 0"/>
        <parent link="robot_body"/>
        <child link="l_wheel"/>  
        <axis xyz='0 0 1'/>      
    </joint>

    <link name="l_wheel">
        <visual>
            <origin xyz="0.17 -0.16 -0.038" rpy="0 -1.57 0"/>
                <geometry>
                    <mesh filename="package://description/meshes/robot_b/robot_b_l_wheel.stl" scale="0.001 0.001 0.001"/>
                </geometry>
        </visual>
        <collision>
            <origin xyz="0.17 -0.16 -0.038" rpy="0 -1.57 0"/>
                <geometry>
                    <mesh filename="package://description/meshes/robot_b/robot_b_l_wheel.stl" scale="0.001 0.001 0.001"/>
                </geometry>
        </collision>
    </link>
    <!-- <gazebo reference='l_wheel'>
        <material>Gazebo/Black</material>
    </gazebo> -->

</robot>